<?xml version="1.0" ?>
<robot name="my_bot1" xmlns:xacro="http://www.ros.org/wiki/xacro">

<link name="base_footprint" />

<link name="base_link">
  <inertial>
    <origin xyz="-0.001991305297947316 -1.8711830484880865e-17 0.050867645575810846" rpy="0 0 0"/>
    <mass value="2.262073723222793"/>
    <inertia ixx="0.031664" iyy="0.083155" izz="0.107459" ixy="-0.0" iyz="-0.0" ixz="0.000845"/>
  </inertial>
  <visual>
    <origin xyz="0 0 0" rpy="0 0 0"/>
    <geometry>
      <mesh filename="file://$(find my_bot1_description)/meshes/base_link.stl" scale="0.001 0.001 0.001"/>
    </geometry>
    <material name="silver"/>
  </visual>
  <collision>
    <origin xyz="0 0 0" rpy="0 0 0"/>
    <geometry>
      <mesh filename="file://$(find my_bot1_description)/meshes/base_link.stl" scale="0.001 0.001 0.001"/>
    </geometry>
  </collision>
</link>

<link name="lidar_1">
  <inertial>
    <origin xyz="0.0 -2.0104246875423704e-17 0.0050000000000000044" rpy="0 0 0"/>
    <mass value="0.22195352097611892"/>
    <inertia ixx="5.2e-05" iyy="5.2e-05" izz="0.0001" ixy="0.0" iyz="-0.0" ixz="0.0"/>
  </inertial>
  <visual>
    <origin xyz="0.065 0.0 -0.095" rpy="0 0 0"/>
    <geometry>
      <mesh filename="file://$(find my_bot1_description)/meshes/lidar_1.stl" scale="0.001 0.001 0.001"/>
    </geometry>
    <material name="silver"/>
  </visual>
  <collision>
    <origin xyz="0.065 0.0 -0.095" rpy="0 0 0"/>
    <geometry>
      <mesh filename="file://$(find my_bot1_description)/meshes/lidar_1.stl" scale="0.001 0.001 0.001"/>
    </geometry>
  </collision>
</link>

<link name="camera_1">
  <inertial>
    <origin xyz="0.010000000000000023 -6.661338147750939e-18 0.0050000000000000044" rpy="0 0 0"/>
    <mass value="0.015699999999999995"/>
    <inertia ixx="1e-06" iyy="0.0" izz="1e-06" ixy="0.0" iyz="-0.0" ixz="0.0"/>
  </inertial>
  <visual>
    <origin xyz="0.125 -0.0 -0.075" rpy="0 0 0"/>
    <geometry>
      <mesh filename="file://$(find my_bot1_description)/meshes/camera_1.stl" scale="0.001 0.001 0.001"/>
    </geometry>
    <material name="silver"/>
  </visual>
  <collision>
    <origin xyz="0.125 -0.0 -0.075" rpy="0 0 0"/>
    <geometry>
      <mesh filename="file://$(find my_bot1_description)/meshes/camera_1.stl" scale="0.001 0.001 0.001"/>
    </geometry>
  </collision>
</link>

<link name="right_wheel_1">
  <inertial>
    <origin xyz="0.0 0.010000000000000009 -6.938893903907228e-18" rpy="0 0 0"/>
    <mass value="0.789168074581756"/>
    <inertia ixx="0.000342" iyy="0.000631" izz="0.000342" ixy="-0.0" iyz="0.0" ixz="0.0"/>
  </inertial>
  <visual>
    <origin xyz="-0.095 -0.09 -0.04" rpy="0 0 0"/>
    <geometry>
      <mesh filename="file://$(find my_bot1_description)/meshes/right_wheel_1.stl" scale="0.001 0.001 0.001"/>
    </geometry>
    <material name="silver"/>
  </visual>
  <collision>
    <origin xyz="-0.095 -0.09 -0.04" rpy="0 0 0"/>
    <geometry>
      <mesh filename="file://$(find my_bot1_description)/meshes/right_wheel_1.stl" scale="0.001 0.001 0.001"/>
    </geometry>
  </collision>
</link>

<link name="caster_wheel_1">
  <inertial>
    <origin xyz="-1.3877787807814457e-17 -2.5200517272015476e-18 -0.003992604884490872" rpy="0 0 0"/>
    <mass value="0.027666894768023"/>
    <inertia ixx="1e-06" iyy="1e-06" izz="2e-06" ixy="-0.0" iyz="-0.0" ixz="-0.0"/>
  </inertial>
  <visual>
    <origin xyz="0.095 0.0 -0.01" rpy="0 0 0"/>
    <geometry>
      <mesh filename="file://$(find my_bot1_description)/meshes/caster_wheel_1.stl" scale="0.001 0.001 0.001"/>
    </geometry>
    <material name="silver"/>
  </visual>
  <collision>
    <origin xyz="0.095 0.0 -0.01" rpy="0 0 0"/>
    <geometry>
      <mesh filename="file://$(find my_bot1_description)/meshes/caster_wheel_1.stl" scale="0.001 0.001 0.001"/>
    </geometry>
  </collision>
</link>

<link name="left_wheel_1">
  <inertial>
    <origin xyz="-1.942890293094024e-16 -0.009999999999999981 -4.85722573273506e-17" rpy="0 0 0"/>
    <mass value="0.789168074581756"/>
    <inertia ixx="0.000342" iyy="0.000631" izz="0.000342" ixy="-0.0" iyz="0.0" ixz="0.0"/>
  </inertial>
  <visual>
    <origin xyz="-0.095 0.09 -0.04" rpy="0 0 0"/>
    <geometry>
      <mesh filename="file://$(find my_bot1_description)/meshes/left_wheel_1.stl" scale="0.001 0.001 0.001"/>
    </geometry>
    <material name="silver"/>
  </visual>
  <collision>
    <origin xyz="-0.095 0.09 -0.04" rpy="0 0 0"/>
    <geometry>
      <mesh filename="file://$(find my_bot1_description)/meshes/left_wheel_1.stl" scale="0.001 0.001 0.001"/>
    </geometry>
  </collision>
</link>

<joint name="base_joint" type="fixed">
  <origin xyz="0.0 0.0 0.01" rpy="0 0 0"/>
  <parent link="base_footprint"/>
  <child link="base_link"/>
</joint>

<joint name="lidar_joint" type="fixed">
  <origin xyz="-0.065 0.0 0.095" rpy="0 0 0"/>
  <parent link="base_link"/>
  <child link="lidar_1"/>
</joint>

<joint name="camera_joint" type="fixed">
  <origin xyz="-0.125 0.0 0.075" rpy="0 0 0"/>
  <parent link="base_link"/>
  <child link="camera_1"/>
</joint>

<joint name="right_wheel_joint" type="continuous">
  <origin xyz="0.095 0.09 0.04" rpy="0 0 0"/>
  <parent link="base_link"/>
  <child link="right_wheel_1"/>
  <axis xyz="0.0 -1.0 0.0"/>
</joint>

<joint name="caster_wheel_joint" type="fixed">
  <origin xyz="-0.095 0.0 0.01" rpy="0 0 0"/>
  <parent link="base_link"/>
  <child link="caster_wheel_1"/>
</joint>

<joint name="left_wheel_joint" type="continuous">
  <origin xyz="0.095 -0.09 0.04" rpy="0 0 0"/>
  <parent link="base_link"/>
  <child link="left_wheel_1"/>
  <axis xyz="0.0 -1.0 0.0"/>
</joint>

</robot>